WARNING  urllib3.connectionpool:connectionpool.py:824 Retrying (Retry(total=2, connect=None, read=None, redirect=None, status=None)) after connection broken by 'NewConnectionError('<urllib3.connection.HTTPSConnection object at 0x0000021B533BE490>: Failed to establish a new connection: [Errno 11001] getaddrinfo failed')': /session
WARNING  urllib3.connectionpool:connectionpool.py:824 Retrying (Retry(total=1, connect=None, read=None, redirect=None, status=None)) after connection broken by 'NewConnectionError('<urllib3.connection.HTTPSConnection object at 0x0000021B533BE9D0>: Failed to establish a new connection: [Errno 11001] getaddrinfo failed')': /session
WARNING  urllib3.connectionpool:connectionpool.py:824 Retrying (Retry(total=0, connect=None, read=None, redirect=None, status=None)) after connection broken by 'NewConnectionError('<urllib3.connection.HTTPSConnection object at 0x0000021B533BF5D0>: Failed to establish a new connection: [Errno 11001] getaddrinfo failed')': /session